---
title: C++新特性梳理系列：C++11 异常处理相关新特性
date: 2021-06-01 23:21:34
tags:
- exception
---

## 前言

C++中异常相关的类和函数都包含在`<exception>`里，包括std::exception，std::bad_exception等等。C++11新增了一些类和函数，相当于扩展了C++的异常机制，新增的内容包括：

- std::nested_exception，这是一个组合类型，即其内部成员包含了std::exception，相比于std::exception，std::nested_exception能用在嵌套抛出异常的场景中且可以保存每一层的异常信息。可能不太好理解，稍后会有示例帮助各位理解。
- std::exception_ptr，这是一个shared_ptr，指向异常对象，可以通过判断是否为nullptr来判断是否有异常，也可以将其保存下来传递给其他函数或者线程。
- current_exception，捕获异常并返回一个std::exception_ptr。
- rethrow_exception，接受一个std::exception_ptr，将此异常对象重新抛出。
- throw_with_nested，接受一个std::nested_exception，即以嵌套的方式抛出。
- rethrow_if_nested，接受一个std::nested_exception，如果该异常对象是嵌套的异常对象才会重新抛出。

## 使用

下面以一个示例介绍以上新增的类和函数：

```c++
void printException(const std::exception& e)
{
    std::cerr << "exception: " << e.what() << std::endl;
    try {
        std::rethrow_if_nested(e);
    } catch (const std::exception& e) {
        printException(e);
    } catch (...) {

    }
}

void boringFunc1()
{
    try {
        std::string().at(1);
    } catch (...) {
        std::throw_with_nested(std::runtime_error("boringFunc1 faild"));
    }
}

void boringFunc()
{
    try {
        boringFunc1();
    } catch (...) {
        std::throw_with_nested(std::runtime_error("boringFunc faild"));
    }
}

void handleException(std::exception_ptr eptr) {
    try {
        if (eptr) {
            std::rethrow_exception(eptr);
        }
    } catch (const std::exception& e) {
        printException(e);
    }
}

int main()
{
    try {
        boringFunc();
    } catch (...) {
        std::exception_ptr eptr = std::current_exception();
        handleException(eptr);
    }
}
```

输出是这样的：

```shell
exception: boringFunc faild
exception: boringFunc2 faild
exception: basic_string::at: __n (which is 1) >= this->size() (which is 0)
```

这个示例稍微有些刻意了，仅作为示例，正常使用不用搞的那么复杂，我大概解释一下嵌套异常：

1. 在boringFunc1中发生了异常（out of range），由于被try-catch包起来，所以不会直接挂掉。在catch里调用了std::throw_with_nested以嵌套的方式抛出异常，boringFunc同理，注意此时又新建了一个异常对象。但boringFunc1里的异常对象并没有被覆盖掉，而是被保存起来了，这个结构类似栈，此时boringFunc的异常对象在栈顶，std::string().at(1)导致的out-of-range异常在栈底。
2. 然后调用栈弹出，回到main函数，触发了catch，这里首先捕获异常，然后丢到handleException函数里去处理异常。
3. 在handleException里判断std::exception_ptr，不为空则抛出异常并且被catch捕获，之后调用printException，在printException里调用了std::exception::what来打印异常信息，然后调用std::rethrow_if_nested来重新抛出这个嵌套的异常对象。同样会被catch，catch里递归的调用printException来打印下一次信息。
4. 在1中有说到，嵌套异常对象的存储是栈式存储的，所以打印的顺序是boringFunc,boringFunc2,out-of-range，如输出所示。

## 小结

本文的内容介绍的比较简单，一是因为在我们的项目中其实使用到异常机制的地方不多，因为我们的场景一旦发生了异常，大部分都是不可自动恢复的，如果发生了异常也最好直接让他crash，方便定位问题。当然如果这个异常是可以恢复的，使用异常处理机制来处理异常也是不错的选择。另外标准库中很多都用到了异常机制。

本文也是C++11新特性系列的最后一篇文章了，C++11新增的东西不只本系列文章提到的，还有例如std::remove_reference等这种日常很少用到的（一般是库的开发者会用到，或者实现一些trick的功能），各位可以通过查阅文档或者在写代码的过程中去了解，之后将开启C++14新特性系列。

## 进度



- [x] [atomic operations library](https://en.cppreference.com/w/cpp/atomic)
- [x] smart pointer
- [x] [std::initializer_list](https://en.cppreference.com/w/cpp/utility/initializer_list)
- [x] [chrono library](https://en.cppreference.com/w/cpp/chrono)
- [x] [ratio library](https://en.cppreference.com/w/cpp/numeric/ratio)
- [x] new [algorithms](https://en.cppreference.com/w/cpp/algorithm):
  - [x] [std::all_of](https://en.cppreference.com/w/cpp/algorithm/all_any_none_of), [std::any_of](https://en.cppreference.com/w/cpp/algorithm/all_any_none_of), [std::none_of](https://en.cppreference.com/w/cpp/algorithm/all_any_none_of),
  - [x] [std::find_if_not](https://en.cppreference.com/w/cpp/algorithm/find),
  - [x] [std::copy_if](https://en.cppreference.com/w/cpp/algorithm/copy), [std::copy_n](https://en.cppreference.com/w/cpp/algorithm/copy_n),
  - [x] [std::random_shuffle](https://en.cppreference.com/w/cpp/algorithm/random_shuffle), [std::shuffle](https://en.cppreference.com/w/cpp/algorithm/random_shuffle),
  - [x] [std::is_partitioned](https://en.cppreference.com/w/cpp/algorithm/is_partitioned), [std::partition_copy](https://en.cppreference.com/w/cpp/algorithm/partition_copy), [std::partition_point](https://en.cppreference.com/w/cpp/algorithm/partition_point),
  - [x] [std::is_sorted](https://en.cppreference.com/w/cpp/algorithm/is_sorted), [std::is_sorted_until](https://en.cppreference.com/w/cpp/algorithm/is_sorted_until),
  - [x] [std::is_heap](https://en.cppreference.com/w/cpp/algorithm/is_heap), [std::is_heap_until](https://en.cppreference.com/w/cpp/algorithm/is_heap_until),
  - [x] [std::minmax](https://en.cppreference.com/w/cpp/algorithm/minmax), [std::minmax_element](https://en.cppreference.com/w/cpp/algorithm/minmax_element),
  - [x] [std::is_permutation](https://en.cppreference.com/w/cpp/algorithm/is_permutation),
  - [x] [std::iota](https://en.cppreference.com/w/cpp/algorithm/iota),
  - [x] [std::uninitialized_copy_n](https://en.cppreference.com/w/cpp/memory/uninitialized_copy_n)
- [x] [thread library](https://en.cppreference.com/w/cpp/thread)
- [x] [std::function](https://en.cppreference.com/w/cpp/utility/functional/function)
- [x] std::bind
- [x] std::exception_ptr